Workbook

Sheet To do
B2: To do:
B3: Add chart on net worth by quintile?
B4: Include waterfall chart that builds up to household income?
B5: Include pie chart for household expenditure?
B7: Key insight:
B8: ~60% of Canadians are in a negative cash flow situation
B9: Bottom Canadians are paying for their expenses with student loans / LOC / gifts from parents / credit cards / spending down their savings? What else?
B10: Income / cash flow inequality is increasing over time -- gap between top 20% and bottom 20% is increasing over time (even adjusting for inflation)
B12: For website:
B14: Put each chart in a separate H2 that be can navigated to easily / link shared indepdently
B15: Table of contents / back to top buttons
B16: Button to click to generate shareable link
... B18: Need URI parameter functionality for the dynamic charts?

Sheet 2023 Drill Down
B1: Annual Household Income
B2: $ per Household, 2023
C3: Age Group
B4: Income Quintile | C4: Less than 35 years | D4: 35 to 44 years | E4: 45 to 54 years | F4: 55 to 64 years | G4: 65 years and over | H4: All
B5: 1 | C5: ='2023 per HH by Age and Quintile'!M16 -> 32144 | D5: ='2023 per HH by Age and Quintile'!N16 -> 39230 | E5: ='2023 per HH by Age and Quintile'!O16 -> 39715 | F5: ='2023 per HH by Age and Quintile'!P16 -> 24610 | G5: ='2023 per HH by Age and Quintile'!Q16 -> 28735 | H5: ='2023 per HH by Age and Quintile'!C16 -> 31604
B6: 2 | C6: ='2023 per HH by Age and Quintile'!R16 -> 75128 | D6: ='2023 per HH by Age and Quintile'!S16 -> 79366 | E6: ='2023 per HH by Age and Quintile'!T16 -> 62668 | F6: ='2023 per HH by Age and Quintile'!U16 -> 55594 | G6: ='2023 per HH by Age and Quintile'!V16 -> 44502 | H6: ='2023 per HH by Age and Quintile'!D16 -> 59447
B7: 3 | C7: ='2023 per HH by Age and Quintile'!W16 -> 89104 | D7: ='2023 per HH by Age and Quintile'!X16 -> 93589 | E7: ='2023 per HH by Age and Quintile'!Y16 -> 98250 | F7: ='2023 per HH by Age and Quintile'!Z16 -> 70228 | G7: ='2023 per HH by Age and Quintile'!AA16 -> 58049 | H7: ='2023 per HH by Age and Quintile'!E16 -> 78998
B8: 4 | C8: ='2023 per HH by Age and Quintile'!AB16 -> 119463 | D8: ='2023 per HH by Age and Quintile'!AC16 -> 137538 | E8: ='2023 per HH by Age and Quintile'!AD16 -> 135803 | F8: ='2023 per HH by Age and Quintile'!AE16 -> 106872 | G8: ='2023 per HH by Age and Quintile'!AF16 -> 79024 | H8: ='2023 per HH by Age and Quintile'!F16 -> 114315
B9: 5 | C9: ='2023 per HH by Age and Quintile'!AG16 -> 182418 | D9: ='2023 per HH by Age and Quintile'!AH16 -> 187629 | E9: ='2023 per HH by Age and Quintile'!AI16 -> 262002 | F9: ='2023 per HH by Age and Quintile'!AJ16 -> 193320 | G9: ='2023 per HH by Age and Quintile'!AK16 -> 167492 | H9: ='2023 per HH by Age and Quintile'!G16 -> 197667
B10: All | C10: ='2023 per HH by Age and Quintile'!H16 -> 97767 | D10: ='2023 per HH by Age and Quintile'!I16 -> 112274 | E10: ='2023 per HH by Age and Quintile'!J16 -> 130133 | F10: ='2023 per HH by Age and Quintile'!K16 -> 101450 | G10: ='2023 per HH by Age and Quintile'!L16 -> 65738 | H10: ='2023 per HH by Age and Quintile'!B16 -> 96406
B15: Annual Household Spending
B16: $ per Household, 2023
C17: Age Group
B18: Income Quintile | C18: Less than 35 years | D18: 35 to 44 years | E18: 45 to 54 years | F18: 55 to 64 years | G18: 65 years and over | H18: All
B19: 1 | C19: ='2023 per HH by Age and Quintile'!M23 -> 62761 | D19: ='2023 per HH by Age and Quintile'!N23 -> 63254 | E19: ='2023 per HH by Age and Quintile'!O23 -> 76767 | F19: ='2023 per HH by Age and Quintile'!P23 -> 71238 | G19: ='2023 per HH by Age and Quintile'!Q23 -> 52572 | H19: {=TRANSPOSE('2023 per HH by Age and Quintile'!C23:G23)} -> 61968
B20: 2 | C20: ='2023 per HH by Age and Quintile'!R23 -> 81310 | D20: ='2023 per HH by Age and Quintile'!S23 -> 97176 | E20: ='2023 per HH by Age and Quintile'!T23 -> 86855 | F20: ='2023 per HH by Age and Quintile'!U23 -> 84889 | G20: ='2023 per HH by Age and Quintile'!V23 -> 55746 | H20: 75118
B21: 3 | C21: ='2023 per HH by Age and Quintile'!W23 -> 88214 | D21: ='2023 per HH by Age and Quintile'!X23 -> 99908 | E21: ='2023 per HH by Age and Quintile'!Y23 -> 126342 | F21: ='2023 per HH by Age and Quintile'!Z23 -> 93812 | G21: ='2023 per HH by Age and Quintile'!AA23 -> 68078 | H21: 91266
B22: 4 | C22: ='2023 per HH by Age and Quintile'!AB23 -> 88615 | D22: ='2023 per HH by Age and Quintile'!AC23 -> 112438 | E22: ='2023 per HH by Age and Quintile'!AD23 -> 135533 | F22: ='2023 per HH by Age and Quintile'!AE23 -> 114766 | G22: ='2023 per HH by Age and Quintile'!AF23 -> 72967 | H22: 103168
B23: 5 | C23: ='2023 per HH by Age and Quintile'!AG23 -> 128919 | D23: ='2023 per HH by Age and Quintile'!AH23 -> 131586 | E23: ='2023 per HH by Age and Quintile'!AI23 -> 183861 | F23: ='2023 per HH by Age and Quintile'!AJ23 -> 146632 | G23: ='2023 per HH by Age and Quintile'!AK23 -> 96602 | H23: 137015
B24: All | C24: ='2023 per HH by Age and Quintile'!H23 -> 88914 | D24: ='2023 per HH by Age and Quintile'!I23 -> 103075 | E24: ='2023 per HH by Age and Quintile'!J23 -> 127283 | F24: ='2023 per HH by Age and Quintile'!K23 -> 107382 | G24: ='2023 per HH by Age and Quintile'!L23 -> 65742 | H24: ='2023 per HH by Age and Quintile'!B23 -> 93707
B29: Annual Cash Flow (excl. pension entitlements)
B30: $ per Household, 2023
C31: Age Group
B32: Income Quintile | C32: Less than 35 years | D32: 35 to 44 years | E32: 45 to 54 years | F32: 55 to 64 years | G32: 65 years and over | H32: All
B33: 1 | C33: =C5-C19 -> -30617 | D33: =D5-D19 -> -24024 | E33: =E5-E19 -> -37052 | F33: =F5-F19 -> -46628 | G33: =G5-G19 -> -23837 | H33: =H5-H19 -> -30364
B34: 2 | C34: =C6-C20 -> -6182 | D34: =D6-D20 -> -17810 | E34: =E6-E20 -> -24187 | F34: =F6-F20 -> -29295 | G34: =G6-G20 -> -11244 | H34: =H6-H20 -> -15671
B35: 3 | C35: =C7-C21 -> 890 | D35: =D7-D21 -> -6319 | E35: =E7-E21 -> -28092 | F35: =F7-F21 -> -23584 | G35: =G7-G21 -> -10029 | H35: =H7-H21 -> -12268
B36: 4 | C36: =C8-C22 -> 30848 | D36: =D8-D22 -> 25100 | E36: =E8-E22 -> 270 | F36: =F8-F22 -> -7894 | G36: =G8-G22 -> 6057 | H36: =H8-H22 -> 11147
B37: 5 | C37: =C9-C23 -> 53499 | D37: =D9-D23 -> 56043 | E37: =E9-E23 -> 78141 | F37: =F9-F23 -> 46688 | G37: =G9-G23 -> 70890 | H37: =H9-H23 -> 60652
B38: All | C38: =C10-C24 -> 8853 | D38: =D10-D24 -> 9199 | E38: =E10-E24 -> 2850 | F38: =F10-F24 -> -5932 | G38: =G10-G24 -> -4 | H38: =H10-H24 -> 2699
B43: Implied Savings Rate
B44: Annual cash flow as a % of annual income
C45: Age Group
B46: Income Quintile | C46: Less than 35 years | D46: 35 to 44 years | E46: 45 to 54 years | F46: 55 to 64 years | G46: 65 years and over | H46: All
B47: 1 | C47: =C33/C5 -> -0.95249502 | D47: =D33/D5 -> -0.61238848 | E47: =E33/E5 -> -0.93294725 | F47: =F33/F5 -> -1.894677 | G47: =G33/G5 -> -0.82954585 | H47: =H33/H5 -> -0.96076446
B48: 2 | C48: =C34/C6 -> -0.082286231 | D48: =D34/D6 -> -0.2244034 | E48: =E34/E6 -> -0.38595455 | F48: =F34/F6 -> -0.52694535 | G48: =G34/G6 -> -0.2526628 | H48: =H34/H6 -> -0.26361297
B49: 3 | C49: =C35/C7 -> 0.0099883282 | D49: =D35/D7 -> -0.067518619 | E49: =E35/E7 -> -0.28592366 | F49: =F35/F7 -> -0.33582047 | G49: =G35/G7 -> -0.17276783 | H49: =H35/H7 -> -0.15529507
B50: 4 | C50: =C36/C8 -> 0.25822221 | D50: =D36/D8 -> 0.18249502 | E50: =E36/E8 -> 0.001988174 | F50: =F36/F8 -> -0.073864062 | G50: =G36/G8 -> 0.076647601 | H50: =H36/H8 -> 0.097511263
B51: 5 | C51: =C37/C9 -> 0.29327698 | D51: =D37/D9 -> 0.2986905 | E51: =E37/E9 -> 0.29824581 | F51: =F37/F9 -> 0.24150631 | G51: =G37/G9 -> 0.4232441 | H51: =H37/H9 -> 0.30683928
B52: All | C52: =C38/C10 -> 0.090552027 | D52: =D38/D10 -> 0.081933484 | E52: =E38/E10 -> 0.021900671 | F52: =F38/F10 -> -0.058472154 | G52: =G38/G10 -> -6.0847607e-05 | H52: =H38/H10 -> 0.027996183

Sheet All Ages Over Time
B2: All Ages
B3: Current Prices, per HH
C4: 1999 | D4: =C4+1 -> 2000 | E4: =D4+1 -> 2001 | F4: =E4+1 -> 2002 | G4: =F4+1 -> 2003 | H4: =G4+1 -> 2004 | I4: =H4+1 -> 2005 | J4: =I4+1 -> 2006 | K4: =J4+1 -> 2007 | ... AA4: =Z4+1 -> 2023
B5: Quintile 1
B6: Income | C6: ='All Ages Over Time Data'!B14 -> 14555 | D6: ='All Ages Over Time Data'!C14 -> 14731 | E6: ='All Ages Over Time Data'!D14 -> 15985 | F6: ='All Ages Over Time Data'!E14 -> 16110 | G6: ='All Ages Over Time Data'!F14 -> 16719 | H6: ='All Ages Over Time Data'!G14 -> 16792 | I6: ='All Ages Over Time Data'!H14 -> 16468 | J6: ='All Ages Over Time Data'!I14 -> 18060 | ... AA6: ='All Ages Over Time Data'!Z14 -> 31604
B7: Spending | C7: ='All Ages Over Time Data'!B21 -> 24102 | D7: ='All Ages Over Time Data'!C21 -> 25810 | E7: ='All Ages Over Time Data'!D21 -> 25104 | F7: ='All Ages Over Time Data'!E21 -> 27210 | G7: ='All Ages Over Time Data'!F21 -> 27705 | H7: ='All Ages Over Time Data'!G21 -> 29959 | I7: ='All Ages Over Time Data'!H21 -> 32395 | J7: ='All Ages Over Time Data'!I21 -> 35870 | ... AA7: ='All Ages Over Time Data'!Z21 -> 61968
B8: Cash Flow | C8: =C6-C7 -> -9547 | D8: =D6-D7 -> -11079 | E8: =E6-E7 -> -9119 | F8: =F6-F7 -> -11100 | G8: =G6-G7 -> -10986 | H8: =H6-H7 -> -13167 | I8: =I6-I7 -> -15927 | J8: =J6-J7 -> -17810 | ... AA8: =AA6-AA7 -> -30364
B9: Y/Y Change | D9: =D8/C8-1 -> 0.16046926 | E9: =E8/D8-1 -> -0.17691127 | F9: =F8/E8-1 -> 0.21723873 | G9: =G8/F8-1 -> -0.01027027 | H9: =H8/G8-1 -> 0.1985254 | I9: =I8/H8-1 -> 0.20961495 | J9: =J8/I8-1 -> 0.11822691 | K9: =K8/J8-1 -> 0.029365525 | ... AA9: =AA8/Z8-1 -> 0.058310969
B11: Quintile 2
B12: Income | C12: ='All Ages Over Time Data'!AA14 -> 28992 | D12: ='All Ages Over Time Data'!AB14 -> 29772 | E12: ='All Ages Over Time Data'!AC14 -> 31982 | F12: ='All Ages Over Time Data'!AD14 -> 32572 | G12: ='All Ages Over Time Data'!AE14 -> 32696 | H12: ='All Ages Over Time Data'!AF14 -> 33458 | I12: ='All Ages Over Time Data'!AG14 -> 34434 | J12: ='All Ages Over Time Data'!AH14 -> 36489 | ... AA12: ='All Ages Over Time Data'!AY14 -> 59447
B13: Spending | C13: ='All Ages Over Time Data'!AA21 -> 35653 | D13: ='All Ages Over Time Data'!AB21 -> 36532 | E13: ='All Ages Over Time Data'!AC21 -> 37719 | F13: ='All Ages Over Time Data'!AD21 -> 39584 | G13: ='All Ages Over Time Data'!AE21 -> 40794 | H13: ='All Ages Over Time Data'!AF21 -> 42638 | I13: ='All Ages Over Time Data'!AG21 -> 44142 | J13: ='All Ages Over Time Data'!AH21 -> 45967 | ... AA13: ='All Ages Over Time Data'!AY21 -> 75118
B14: Cash Flow | C14: =C12-C13 -> -6661 | D14: =D12-D13 -> -6760 | E14: =E12-E13 -> -5737 | F14: =F12-F13 -> -7012 | G14: =G12-G13 -> -8098 | H14: =H12-H13 -> -9180 | I14: =I12-I13 -> -9708 | J14: =J12-J13 -> -9478 | ... AA14: =AA12-AA13 -> -15671
B15: Y/Y Change | D15: =D14/C14-1 -> 0.014862633 | E15: =E14/D14-1 -> -0.15133136 | F15: =F14/E14-1 -> 0.22224159 | G15: =G14/F14-1 -> 0.15487735 | H15: =H14/G14-1 -> 0.13361324 | I15: =I14/H14-1 -> 0.05751634 | J15: =J14/I14-1 -> -0.023691801 | K15: =K14/J14-1 -> 0.10592952 | ... AA15: =AA14/Z14-1 -> 0.20157951
B17: Quintile 3
B18: Income | C18: ='All Ages Over Time Data'!AZ14 -> 40456 | D18: ='All Ages Over Time Data'!BA14 -> 41187 | E18: ='All Ages Over Time Data'!BB14 -> 42930 | F18: ='All Ages Over Time Data'!BC14 -> 43409 | G18: ='All Ages Over Time Data'!BD14 -> 44902 | H18: ='All Ages Over Time Data'!BE14 -> 45754 | I18: ='All Ages Over Time Data'!BF14 -> 46857 | J18: ='All Ages Over Time Data'!BG14 -> 49509 | ... AA18: ='All Ages Over Time Data'!BX14 -> 78998
B19: Spending | C19: ='All Ages Over Time Data'!AZ21 -> 45044 | D19: ='All Ages Over Time Data'!BA21 -> 46513 | E19: ='All Ages Over Time Data'!BB21 -> 48811 | F19: ='All Ages Over Time Data'!BC21 -> 50036 | G19: ='All Ages Over Time Data'!BD21 -> 51391 | H19: ='All Ages Over Time Data'!BE21 -> 52277 | I19: ='All Ages Over Time Data'!BF21 -> 54391 | J19: ='All Ages Over Time Data'!BG21 -> 56189 | ... AA19: ='All Ages Over Time Data'!BX21 -> 91266
B20: Cash Flow | C20: =C18-C19 -> -4588 | D20: =D18-D19 -> -5326 | E20: =E18-E19 -> -5881 | F20: =F18-F19 -> -6627 | G20: =G18-G19 -> -6489 | H20: =H18-H19 -> -6523 | I20: =I18-I19 -> -7534 | J20: =J18-J19 -> -6680 | ... AA20: =AA18-AA19 -> -12268
B21: Y/Y Change | D21: =D20/C20-1 -> 0.1608544 | E21: =E20/D20-1 -> 0.10420578 | F21: =F20/E20-1 -> 0.12684918 | G21: =G20/F20-1 -> -0.020823902 | H21: =H20/G20-1 -> 0.0052396363 | I21: =I20/H20-1 -> 0.15499004 | J21: =J20/I20-1 -> -0.1133528 | K21: =K20/J20-1 -> 0.087275449 | ... AA21: =AA20/Z20-1 -> 0.14922717
B23: Quintile 4
B24: Income | C24: ='All Ages Over Time Data'!BY14 -> 53967 | D24: ='All Ages Over Time Data'!BZ14 -> 55257 | E24: ='All Ages Over Time Data'!CA14 -> 57948 | F24: ='All Ages Over Time Data'!CB14 -> 60528 | G24: ='All Ages Over Time Data'!CC14 -> 60636 | H24: ='All Ages Over Time Data'!CD14 -> 62590 | I24: ='All Ages Over Time Data'!CE14 -> 64135 | J24: ='All Ages Over Time Data'!CF14 -> 66336 | ... AA24: ='All Ages Over Time Data'!CW14 -> 114315
B25: Spending | C25: ='All Ages Over Time Data'!BY21 -> 53527 | D25: ='All Ages Over Time Data'!BZ21 -> 56197 | E25: ='All Ages Over Time Data'!CA21 -> 58443 | F25: ='All Ages Over Time Data'!CB21 -> 60269 | G25: ='All Ages Over Time Data'!CC21 -> 63583 | H25: ='All Ages Over Time Data'!CD21 -> 63006 | I25: ='All Ages Over Time Data'!CE21 -> 65997 | J25: ='All Ages Over Time Data'!CF21 -> 67937 | ... AA25: ='All Ages Over Time Data'!CW21 -> 103168
B26: Cash Flow | C26: =C24-C25 -> 440 | D26: =D24-D25 -> -940 | E26: =E24-E25 -> -495 | F26: =F24-F25 -> 259 | G26: =G24-G25 -> -2947 | H26: =H24-H25 -> -416 | I26: =I24-I25 -> -1862 | J26: =J24-J25 -> -1601 | ... AA26: =AA24-AA25 -> 11147
B27: Y/Y Change | D27: =D26/C26-1 -> -3.1363636 | E27: =E26/D26-1 -> -0.47340426 | F27: =F26/E26-1 -> -1.5232323 | G27: =G26/F26-1 -> -12.378378 | H27: =H26/G26-1 -> -0.8588395 | I27: =I26/H26-1 -> 3.4759615 | J27: =J26/I26-1 -> -0.14017186 | K27: =K26/J26-1 -> 0.18488445 | ... AA27: =AA26/Z26-1 -> 0.023317727
B29: Quintile 5
B30: Income | C30: ='All Ages Over Time Data'!CX14 -> 92502 | D30: ='All Ages Over Time Data'!CY14 -> 99880 | E30: ='All Ages Over Time Data'!CZ14 -> 102327 | F30: ='All Ages Over Time Data'!DA14 -> 105850 | G30: ='All Ages Over Time Data'!DB14 -> 108511 | H30: ='All Ages Over Time Data'!DC14 -> 113861 | I30: ='All Ages Over Time Data'!DD14 -> 117390 | J30: ='All Ages Over Time Data'!DE14 -> 125058 | ... AA30: ='All Ages Over Time Data'!DV14 -> 197667
B31: Spending | C31: ='All Ages Over Time Data'!CX21 -> 75203 | D31: ='All Ages Over Time Data'!CY21 -> 79655 | E31: ='All Ages Over Time Data'!CZ21 -> 81051 | F31: ='All Ages Over Time Data'!DA21 -> 84998 | G31: ='All Ages Over Time Data'!DB21 -> 87129 | H31: ='All Ages Over Time Data'!DC21 -> 91512 | I31: ='All Ages Over Time Data'!DD21 -> 94322 | J31: ='All Ages Over Time Data'!DE21 -> 96839 | ... AA31: ='All Ages Over Time Data'!DV21 -> 137015
B32: Cash Flow | C32: =C30-C31 -> 17299 | D32: =D30-D31 -> 20225 | E32: =E30-E31 -> 21276 | F32: =F30-F31 -> 20852 | G32: =G30-G31 -> 21382 | H32: =H30-H31 -> 22349 | I32: =I30-I31 -> 23068 | J32: =J30-J31 -> 28219 | ... AA32: =AA30-AA31 -> 60652
B33: Y/Y Change | D33: =D32/C32-1 -> 0.16914273 | E33: =E32/D32-1 -> 0.051965389 | F33: =F32/E32-1 -> -0.019928558 | G33: =G32/F32-1 -> 0.025417226 | H33: =H32/G32-1 -> 0.045224956 | I33: =I32/H32-1 -> 0.032171462 | J33: =J32/I32-1 -> 0.22329634 | K33: =K32/J32-1 -> 0.0030121549 | ... AA33: =AA32/Z32-1 -> 0.12210464
B35: CPI | C35: =CPI!B12 -> 92.9 | D35: =CPI!C12 -> 95.4 | E35: =CPI!D12 -> 97.8 | F35: =CPI!E12 -> 100 | G35: =CPI!F12 -> 102.8 | H35: =CPI!G12 -> 104.7 | I35: =CPI!H12 -> 107 | J35: =CPI!I12 -> 109.1 | ... AA35: =CPI!Z12 -> 157.1
B37: Under 35 Age Group -- Per Household Values
B38: 2023 Dollars, per HH
C39: 1999 | D39: =C39+1 -> 2000 | E39: =D39+1 -> 2001 | F39: =E39+1 -> 2002 | G39: =F39+1 -> 2003 | H39: =G39+1 -> 2004 | I39: =H39+1 -> 2005 | J39: =I39+1 -> 2006 | K39: =J39+1 -> 2007 | ... AA39: =Z39+1 -> 2023
B40: Quintile 1
B41: Income | C41: =C6*($AA$35/C$35) -> 24613.461 | D41: =D6*($AA$35/D$35) -> 24258.282 | E41: =E6*($AA$35/E$35) -> 25677.336 | F41: =F6*($AA$35/F$35) -> 25308.81 | G41: =G6*($AA$35/G$35) -> 25550.145 | H41: =H6*($AA$35/H$35) -> 25196.019 | I41: =I6*($AA$35/I$35) -> 24178.718 | J41: =J6*($AA$35/J$35) -> 26005.738 | ... AA41: =AA6*($AA$35/AA$35) -> 31604
B42: Spending | C42: =C7*($AA$35/C$35) -> 40758.065 | D42: =D7*($AA$35/D$35) -> 42502.631 | E42: =E7*($AA$35/E$35) -> 40325.546 | F42: =F7*($AA$35/F$35) -> 42746.91 | G42: =G7*($AA$35/G$35) -> 42339.061 | H42: =H7*($AA$35/H$35) -> 44952.807 | I42: =I7*($AA$35/I$35) -> 47563.126 | J42: =J7*($AA$35/J$35) -> 51651.485 | ... AA42: =AA7*($AA$35/AA$35) -> 61968
B43: Cash Flow | C43: =C41-C42 -> -16144.604 | D43: =D41-D42 -> -18244.349 | E43: =E41-E42 -> -14648.21 | F43: =F41-F42 -> -17438.1 | G43: =G41-G42 -> -16788.916 | H43: =H41-H42 -> -19756.788 | I43: =I41-I42 -> -23384.408 | J43: =J41-J42 -> -25645.747 | ... AA43: =AA41-AA42 -> -30364
B44: Y/Y Change | D44: =D43/C43-1 -> 0.13005864 | E44: =E43/D43-1 -> -0.19710977 | F44: =F43/E43-1 -> 0.19045948 | G44: =G43/F43-1 -> -0.037227889 | H44: =H43/G43-1 -> 0.17677565 | I44: =I43/H43-1 -> 0.18361388 | J44: =J43/I43-1 -> 0.096702836 | K44: =K43/J43-1 -> 0.0072087783 | ... AA44: =AA43/Z43-1 -> 0.018565363
B46: Quintile 2
B47: Income | C47: =C12*($AA$35/C$35) -> 49027.376 | D47: =D12*($AA$35/D$35) -> 49027.057 | E47: =E12*($AA$35/E$35) -> 51373.949 | F47: =F12*($AA$35/F$35) -> 51170.612 | G47: =G12*($AA$35/G$35) -> 49966.358 | H47: =H12*($AA$35/H$35) -> 50202.978 | I47: =I12*($AA$35/I$35) -> 50556.836 | J47: =J12*($AA$35/J$35) -> 52542.822 | ... AA47: =AA12*($AA$35/AA$35) -> 59447
B48: Spending | C48: =C13*($AA$35/C$35) -> 60291.564 | D48: =D13*($AA$35/D$35) -> 60159.09 | E48: =E13*($AA$35/E$35) -> 60589.518 | F48: =F13*($AA$35/F$35) -> 62186.464 | G48: =G13*($AA$35/G$35) -> 62341.804 | H48: =H13*($AA$35/H$35) -> 63977.362 | I48: =I13*($AA$35/I$35) -> 64810.357 | J48: =J13*($AA$35/J$35) -> 66190.795 | ... AA48: =AA13*($AA$35/AA$35) -> 75118
...

Sheet Under 35 Over Time
B2: Under 35 Age Group -- Per Household Values
B3: Current Prices
C4: 1999 | D4: =C4+1 -> 2000 | E4: =D4+1 -> 2001 | F4: =E4+1 -> 2002 | G4: =F4+1 -> 2003 | H4: =G4+1 -> 2004 | I4: =H4+1 -> 2005 | J4: =I4+1 -> 2006 | K4: =J4+1 -> 2007 | ... AA4: =Z4+1 -> 2023
B5: Under 35 -- Lowest Quintile
B6: Income | C6: ='Under 35 per HH Over Time'!B14 -> 14002 | D6: ='Under 35 per HH Over Time'!C14 -> 14089 | E6: ='Under 35 per HH Over Time'!D14 -> 14590 | F6: ='Under 35 per HH Over Time'!E14 -> 14976 | G6: ='Under 35 per HH Over Time'!F14 -> 15216 | H6: ='Under 35 per HH Over Time'!G14 -> 16089 | I6: ='Under 35 per HH Over Time'!H14 -> 15822 | J6: ='Under 35 per HH Over Time'!I14 -> 17790 | ... AA6: ='Under 35 per HH Over Time'!Z14 -> 32144
B7: Spending | C7: ='Under 35 per HH Over Time'!B21 -> 21246 | D7: ='Under 35 per HH Over Time'!C21 -> 23543 | E7: ='Under 35 per HH Over Time'!D21 -> 23106 | F7: ='Under 35 per HH Over Time'!E21 -> 25293 | G7: ='Under 35 per HH Over Time'!F21 -> 25826 | H7: ='Under 35 per HH Over Time'!G21 -> 27761 | I7: ='Under 35 per HH Over Time'!H21 -> 30538 | J7: ='Under 35 per HH Over Time'!I21 -> 35167 | ... AA7: ='Under 35 per HH Over Time'!Z21 -> 62761
B8: Cash Flow | C8: =C6-C7 -> -7244 | D8: =D6-D7 -> -9454 | E8: =E6-E7 -> -8516 | F8: =F6-F7 -> -10317 | G8: =G6-G7 -> -10610 | H8: =H6-H7 -> -11672 | I8: =I6-I7 -> -14716 | J8: =J6-J7 -> -17377 | ... AA8: =AA6-AA7 -> -30617
B9: Y/Y Change | D9: =D8/C8-1 -> 0.30508007 | E9: =E8/D8-1 -> -0.099217263 | F9: =F8/E8-1 -> 0.21148426 | G9: =G8/F8-1 -> 0.028399729 | H9: =H8/G8-1 -> 0.10009425 | I9: =I8/H8-1 -> 0.26079507 | J9: =J8/I8-1 -> 0.18082359 | K9: =K8/J8-1 -> 0.068366231 | ... AA9: =AA8/Z8-1 -> 0.10038097
B11: Under 35 -- Highest Quintile
B12: Income | C12: ='Under 35 per HH Over Time'!AA14 -> 82093 | D12: ='Under 35 per HH Over Time'!AB14 -> 85719 | E12: ='Under 35 per HH Over Time'!AC14 -> 86051 | F12: ='Under 35 per HH Over Time'!AD14 -> 88957 | G12: ='Under 35 per HH Over Time'!AE14 -> 88944 | H12: ='Under 35 per HH Over Time'!AF14 -> 93273 | I12: ='Under 35 per HH Over Time'!AG14 -> 100011 | J12: ='Under 35 per HH Over Time'!AH14 -> 98445 | ... AA12: ='Under 35 per HH Over Time'!AY14 -> 182418
B13: Spending | C13: ='Under 35 per HH Over Time'!AA21 -> 69707 | D13: ='Under 35 per HH Over Time'!AB21 -> 68117 | E13: ='Under 35 per HH Over Time'!AC21 -> 66937 | F13: ='Under 35 per HH Over Time'!AD21 -> 69533 | G13: ='Under 35 per HH Over Time'!AE21 -> 70861 | H13: ='Under 35 per HH Over Time'!AF21 -> 72890 | I13: ='Under 35 per HH Over Time'!AG21 -> 81337 | J13: ='Under 35 per HH Over Time'!AH21 -> 80414 | ... AA13: ='Under 35 per HH Over Time'!AY21 -> 128919
B14: Cash Flow | C14: =C12-C13 -> 12386 | D14: =D12-D13 -> 17602 | E14: =E12-E13 -> 19114 | F14: =F12-F13 -> 19424 | G14: =G12-G13 -> 18083 | H14: =H12-H13 -> 20383 | I14: =I12-I13 -> 18674 | J14: =J12-J13 -> 18031 | ... AA14: =AA12-AA13 -> 53499
B15: Y/Y Change | D15: =D14/C14-1 -> 0.42112062 | E15: =E14/D14-1 -> 0.08589933 | F15: =F14/E14-1 -> 0.016218479 | G15: =G14/F14-1 -> -0.069038303 | H15: =H14/G14-1 -> 0.12719128 | I15: =I14/H14-1 -> -0.08384438 | J15: =J14/I14-1 -> -0.034432901 | K15: =K14/J14-1 -> 0.1949975 | ... AA15: =AA14/Z14-1 -> -0.21098739
B17: CPI | C17: =CPI!B12 -> 92.9 | D17: =CPI!C12 -> 95.4 | E17: =CPI!D12 -> 97.8 | F17: =CPI!E12 -> 100 | G17: =CPI!F12 -> 102.8 | H17: =CPI!G12 -> 104.7 | I17: =CPI!H12 -> 107 | J17: =CPI!I12 -> 109.1 | ... AA17: =CPI!Z12 -> 157.1
B19: Under 35 Age Group -- Per Household Values
B20: 2023 Dollars
C21: 1999 | D21: =C21+1 -> 2000 | E21: =D21+1 -> 2001 | F21: =E21+1 -> 2002 | G21: =F21+1 -> 2003 | H21: =G21+1 -> 2004 | I21: =H21+1 -> 2005 | J21: =I21+1 -> 2006 | K21: =J21+1 -> 2007 | ... AA21: =Z21+1 -> 2023
B22: Under 35 -- Lowest Quintile
B23: Income | C23: =C6*($AA$17/C$17) -> 23678.301 | D23: =D6*($AA$17/D$17) -> 23201.068 | E23: =E6*($AA$17/E$17) -> 23436.493 | F23: =F6*($AA$17/F$17) -> 23527.296 | G23: =G6*($AA$17/G$17) -> 23253.245 | H23: =H6*($AA$17/H$17) -> 24141.183 | I23: =I6*($AA$17/I$17) -> 23230.245 | J23: =J6*($AA$17/J$17) -> 25616.948 | ... AA23: =AA6*($AA$17/AA$17) -> 32144
B24: Spending | C24: =C7*($AA$17/C$17) -> 35928.381 | D24: =D7*($AA$17/D$17) -> 38769.448 | E24: =E7*($AA$17/E$17) -> 37116.08 | F24: =F7*($AA$17/F$17) -> 39735.303 | G24: =G7*($AA$17/G$17) -> 39467.554 | H24: =H7*($AA$17/H$17) -> 41654.757 | I24: =I7*($AA$17/I$17) -> 44836.634 | J24: =J7*($AA$17/J$17) -> 50639.191 | ... AA24: =AA7*($AA$17/AA$17) -> 62761
B25: Cash Flow | C25: =C23-C24 -> -12250.08 | D25: =D23-D24 -> -15568.379 | E25: =E23-E24 -> -13679.587 | F25: =F23-F24 -> -16208.007 | G25: =G23-G24 -> -16214.309 | H25: =H23-H24 -> -17513.574 | I25: =I23-I24 -> -21606.389 | J25: =J23-J24 -> -25022.243 | ... AA25: =AA23-AA24 -> -30617
B26: Y/Y Change | D26: =D25/C25-1 -> 0.27087985 | E26: =E25/D25-1 -> -0.12132236 | F26: =F25/E25-1 -> 0.18483161 | G26: =G25/F25-1 -> 0.00038884105 | H26: =H25/G25-1 -> 0.080130745 | I26: =I25/H25-1 -> 0.23369386 | J26: =J25/I25-1 -> 0.15809463 | K26: =K25/J25-1 -> 0.045370007 | ... AA26: =AA25/Z25-1 -> 0.059055392
B28: Under 35 -- Highest Quintile
B29: Income | C29: =C12*($AA$17/C$17) -> 138824.65 | D29: =D12*($AA$17/D$17) -> 141157.81 | E29: =E12*($AA$17/E$17) -> 138227.12 | F29: =F12*($AA$17/F$17) -> 139751.45 | G29: =G12*($AA$17/G$17) -> 135925.12 | H29: =H12*($AA$17/H$17) -> 139954.04 | I29: =I12*($AA$17/I$17) -> 146838.58 | J29: =J12*($AA$17/J$17) -> 141757.19 | ... AA29: =AA12*($AA$17/AA$17) -> 182418
B30: Spending | C30: =C13*($AA$17/C$17) -> 117879.11 | D30: =D13*($AA$17/D$17) -> 112171.71 | E30: =E13*($AA$17/E$17) -> 107523.54 | F30: =F13*($AA$17/F$17) -> 109236.34 | G30: =G13*($AA$17/G$17) -> 108290.5 | H30: =H13*($AA$17/H$17) -> 109369.81 | I30: =I13*($AA$17/I$17) -> 119420.96 | J30: =J13*($AA$17/J$17) -> 115793.21 | ... AA30: =AA13*($AA$17/AA$17) -> 128919
B31: Cash Flow | C31: =C29-C30 -> 20945.539 | D31: =D29-D30 -> 28986.103 | E31: =E29-E30 -> 30703.573 | F31: =F29-F30 -> 30515.104 | G31: =G29-G30 -> 27634.624 | H31: =H29-H30 -> 30584.234 | I31: =I29-I30 -> 27417.621 | J31: =J29-J30 -> 25963.979 | ... AA31: =AA29-AA30 -> 53499
B32: Y/Y Change | D32: =D31/C31-1 -> 0.38387951 | E32: =E31/D31-1 -> 0.059251493 | F32: =F31/E31-1 -> -0.0061383279 | G32: =G31/F31-1 -> -0.094395237 | H32: =H31/G31-1 -> 0.10673605 | I32: =I31/H31-1 -> -0.10353744 | J32: =J31/I31-1 -> -0.053018519 | K32: =K31/J31-1 -> 0.16927558 | ... AA32: =AA31/Z31-1 -> -0.24061931
B34: Delta | C34: =C31-C25 -> 33195.619 | D34: =D31-D25 -> 44554.482 | E34: =E31-E25 -> 44383.16 | F34: =F31-F25 -> 46723.111 | G34: =G31-G25 -> 43848.933 | H34: =H31-H25 -> 48097.808 | I34: =I31-I25 -> 49024.009 | J34: =J31-J25 -> 50986.222 | ... AA34: =AA31-AA25 -> 84116

Sheet Net Worth
C3: Quintile
B4: Net Worth (Nominal) | C4: 1 | D4: 2 | E4: 3 | F4: 4 | G4: 5 | H4: All
B5: Q4 2010 | C5: ='Net Worth Over Time by Quintile'!BJ24 -> -11976 | D5: ='Net Worth Over Time by Quintile'!DO24 -> 49882 | E5: ='Net Worth Over Time by Quintile'!FT24 -> 219359 | F5: ='Net Worth Over Time by Quintile'!HY24 -> 530601 | G5: ='Net Worth Over Time by Quintile'!KD24 -> 1748713 | H5: ='Net Worth Over Time by Quintile'!E24 -> 507316
B6: Q4 2023 | C6: ='Net Worth Over Time by Quintile'!DJ24 -> -1141 | D6: ='Net Worth Over Time by Quintile'!FO24 -> 135497 | E6: ='Net Worth Over Time by Quintile'!HT24 -> 454074 | F6: ='Net Worth Over Time by Quintile'!JY24 -> 996641 | G6: ='Net Worth Over Time by Quintile'!MD24 -> 3311107 | H6: ='Net Worth Over Time by Quintile'!BE24 -> 979236
B8: CPI
B9: Q4 2010 | H9: =CPI!M12 -> 116.5
B10: Q4 2023 | H10: =CPI!Z12 -> 157.1
C12: Quintile
B13: Net Worth (Real) | C13: Quintile 1 | D13: Quintile 2 | E13: Quintile 3 | F13: Quintile 4 | G13: Quintile 5 | H13: All Quintiles
B14: Q4 2010 | C14: =C5*$H$10/$H$9 -> -16149.61 | D14: =D5*$H$10/$H$9 -> 67265.77 | E14: =E5*$H$10/$H$9 -> 295805.14 | F14: =F5*$H$10/$H$9 -> 715514.31 | G14: =G5*$H$10/$H$9 -> 2358135.7 | H14: =H5*$H$10/$H$9 -> 684114.54
B15: Q4 2023 | C15: =C6 -> -1141 | D15: =D6 -> 135497 | E15: =E6 -> 454074 | F15: =F6 -> 996641 | G15: =G6 -> 3311107 | H15: =H6 -> 979236
B16: $ Change | C16: =C15-C14 -> 15008.61 | D16: =D15-D14 -> 68231.23 | E16: =E15-E14 -> 158268.86 | F16: =F15-F14 -> 281126.69 | G16: =G15-G14 -> 952971.27 | H16: =H15-H14 -> 295121.46
B17: % Change | C17: =C16/C14 -> -0.92934814 | D17: =D16/D14 -> 1.0143529 | E17: =E16/E14 -> 0.53504432 | F17: =F16/F14 -> 0.39290156 | G17: =G16/G14 -> 0.40412062 | H17: =H16/H14 -> 0.43139189

Sheet Net Worth Over Time by Quintile
A1: Distributions of household economic accounts, wealth, by characteristic, Canada, quarterly
A2: Frequency: Quarterly
A3: Table: 36-10-0660-01
A4: Release date: 2024-07-17
A5: Geography: Canada
A6: https://www150.statcan.gc.ca/t1/tbl1/en/cv!recreate.action?pid=3610066001&selectedNodeIds=2D3,3D53,3D54,3D55,3D56,3D57&checkedLevels=0D1,2D1,3D1,3D2,3D3&refPeriods=20100101,20241001&dimensionLayouts=layout2,layout2,layout2,layout3,layout2&vectorDisplay=false
A9: Geography | B9: Canada
A10: Statistics | B10: Value per household
A11: Characteristics | B11: All households | BG11: Lowest wealth quintile 1 2 | DL11: Second wealth quintile 1 2 | FQ11: Third wealth quintile 1 2 | HV11: Fourth wealth quintile 1 2 | KA11: Highest wealth quintile 1 2
A12: Wealth | B12: Q1 2010 | C12: Q2 2010 | D12: Q3 2010 | E12: Q4 2010 | F12: Q1 2011 | G12: Q2 2011 | H12: Q3 2011 | I12: Q4 2011 | J12: Q1 2012 | K12: Q2 2012 | L12: Q3 2012 | M12: Q4 2012 | N12: Q1 2013 | O12: Q2 2013 | P12: Q3 2013 | Q12: Q4 2013 | R12: Q1 2014 | S12: Q2 2014 | T12: Q3 2014 | U12: Q4 2014 | V12: Q1 2015 | W12: Q2 2015 | X12: Q3 2015 | Y12: Q4 2015 | Z12: Q1 2016 | AA12: Q2 2016 | AB12: Q3 2016 | AC12: Q4 2016 | AD12: Q1 2017 | AE12: Q2 2017 | AF12: Q3 2017 | AG12: Q4 2017 | AH12: Q1 2018 | AI12: Q2 2018 | AJ12: Q3 2018 | AK12: Q4 2018 | AL12: Q1 2019 | AM12: Q2 2019 | AN12: Q3 2019 | AO12: Q4 2019 | AP12: Q1 2020 | AQ12: Q2 2020 | AR12: Q3 2020 | AS12: Q4 2020 | AT12: Q1 2021 | AU12: Q2 2021 | AV12: Q3 2021 | AW12: Q4 2021 | AX12: Q1 2022 | AY12: Q2 2022 | AZ12: Q3 2022 | BA12: Q4 2022 | BB12: Q1 2023 | BC12: Q2 2023 | BD12: Q3 2023 | BE12: Q4 2023 | BF12: Q1 2024 | BG12: Q1 2010 | BH12: Q2 2010 | BI12: Q3 2010 | BJ12: Q4 2010 | BK12: Q1 2011 | BL12: Q2 2011 | BM12: Q3 2011 | BN12: Q4 2011 | BO12: Q1 2012 | BP12: Q2 2012 | BQ12: Q3 2012 | BR12: Q4 2012 | BS12: Q1 2013 | BT12: Q2 2013 | BU12: Q3 2013 | BV12: Q4 2013 | BW12: Q1 2014 | BX12: Q2 2014 | BY12: Q3 2014 | BZ12: Q4 2014 | CA12: Q1 2015 | CB12: Q2 2015 | CC12: Q3 2015 | CD12: Q4 2015 | CE12: Q1 2016 | CF12: Q2 2016 | CG12: Q3 2016 | CH12: Q4 2016 | CI12: Q1 2017 | CJ12: Q2 2017 | CK12: Q3 2017 | CL12: Q4 2017 | CM12: Q1 2018 | CN12: Q2 2018 | CO12: Q3 2018 | CP12: Q4 2018 | CQ12: Q1 2019 | CR12: Q2 2019 | CS12: Q3 2019 | CT12: Q4 2019 | CU12: Q1 2020 | CV12: Q2 2020 | CW12: Q3 2020 | CX12: Q4 2020 | CY12: Q1 2021 | CZ12: Q2 2021 | DA12: Q3 2021 | DB12: Q4 2021 | DC12: Q1 2022 | DD12: Q2 2022 | DE12: Q3 2022 | DF12: Q4 2022 | DG12: Q1 2023 | DH12: Q2 2023 | DI12: Q3 2023 | DJ12: Q4 2023 | DK12: Q1 2024 | DL12: Q1 2010 | DM12: Q2 2010 | DN12: Q3 2010 | DO12: Q4 2010 | DP12: Q1 2011 | DQ12: Q2 2011 | DR12: Q3 2011 | DS12: Q4 2011 | DT12: Q1 2012 | DU12: Q2 2012 | DV12: Q3 2012 | DW12: Q4 2012 | DX12: Q1 2013 | DY12: Q2 2013 | DZ12: Q3 2013 | EA12: Q4 2013 | EB12: Q1 2014 | EC12: Q2 2014 | ED12: Q3 2014 | EE12: Q4 2014 | EF12: Q1 2015 | EG12: Q2 2015 | EH12: Q3 2015 | EI12: Q4 2015 | EJ12: Q1 2016 | EK12: Q2 2016 | EL12: Q3 2016 | EM12: Q4 2016 | EN12: Q1 2017 | EO12: Q2 2017 | EP12: Q3 2017 | EQ12: Q4 2017 | ER12: Q1 2018 | ES12: Q2 2018 | ET12: Q3 2018 | EU12: Q4 2018 | EV12: Q1 2019 | EW12: Q2 2019 | EX12: Q3 2019 | EY12: Q4 2019 | EZ12: Q1 2020 | FA12: Q2 2020 | FB12: Q3 2020 | FC12: Q4 2020 | FD12: Q1 2021 | FE12: Q2 2021 | FF12: Q3 2021 | FG12: Q4 2021 | FH12: Q1 2022 | FI12: Q2 2022 | FJ12: Q3 2022 | FK12: Q4 2022 | FL12: Q1 2023 | FM12: Q2 2023 | FN12: Q3 2023 | FO12: Q4 2023 | FP12: Q1 2024 | FQ12: Q1 2010 | FR12: Q2 2010 | FS12: Q3 2010 | FT12: Q4 2010 | FU12: Q1 2011 | FV12: Q2 2011 | FW12: Q3 2011 | FX12: Q4 2011 | FY12: Q1 2012 | FZ12: Q2 2012 | GA12: Q3 2012 | GB12: Q4 2012 | GC12: Q1 2013 | GD12: Q2 2013 | GE12: Q3 2013 | GF12: Q4 2013 | GG12: Q1 2014 | GH12: Q2 2014 | GI12: Q3 2014 | GJ12: Q4 2014 | GK12: Q1 2015 | GL12: Q2 2015 | GM12: Q3 2015 | GN12: Q4 2015 | GO12: Q1 2016 | GP12: Q2 2016 | GQ12: Q3 2016 | GR12: Q4 2016 | GS12: Q1 2017 | GT12: Q2 2017 | GU12: Q3 2017 | GV12: Q4 2017 | GW12: Q1 2018 | GX12: Q2 2018 | GY12: Q3 2018 | GZ12: Q4 2018 | HA12: Q1 2019 | HB12: Q2 2019 | HC12: Q3 2019 | HD12: Q4 2019 | HE12: Q1 2020 | HF12: Q2 2020 | HG12: Q3 2020 | HH12: Q4 2020 | HI12: Q1 2021 | HJ12: Q2 2021 | HK12: Q3 2021 | HL12: Q4 2021 | HM12: Q1 2022 | HN12: Q2 2022 | HO12: Q3 2022 | HP12: Q4 2022 | HQ12: Q1 2023 | HR12: Q2 2023 | HS12: Q3 2023 | HT12: Q4 2023 | HU12: Q1 2024 | HV12: Q1 2010 | HW12: Q2 2010 | HX12: Q3 2010 | HY12: Q4 2010 | HZ12: Q1 2011 | IA12: Q2 2011 | IB12: Q3 2011 | IC12: Q4 2011 | ID12: Q1 2012 | IE12: Q2 2012 | IF12: Q3 2012 | IG12: Q4 2012 | IH12: Q1 2013 | II12: Q2 2013 | IJ12: Q3 2013 | IK12: Q4 2013 | IL12: Q1 2014 | IM12: Q2 2014 | IN12: Q3 2014 | IO12: Q4 2014 | IP12: Q1 2015 | IQ12: Q2 2015 | IR12: Q3 2015 | IS12: Q4 2015 | IT12: Q1 2016 | IU12: Q2 2016 | IV12: Q3 2016 | IW12: Q4 2016 | IX12: Q1 2017 | IY12: Q2 2017 | IZ12: Q3 2017 | JA12: Q4 2017 | JB12: Q1 2018 | JC12: Q2 2018 | JD12: Q3 2018 | JE12: Q4 2018 | JF12: Q1 2019 | JG12: Q2 2019 | JH12: Q3 2019 | JI12: Q4 2019 | JJ12: Q1 2020 | JK12: Q2 2020 | JL12: Q3 2020 | JM12: Q4 2020 | JN12: Q1 2021 | JO12: Q2 2021 | JP12: Q3 2021 | JQ12: Q4 2021 | JR12: Q1 2022 | JS12: Q2 2022 | JT12: Q3 2022 | JU12: Q4 2022 | JV12: Q1 2023 | JW12: Q2 2023 | JX12: Q3 2023 | JY12: Q4 2023 | JZ12: Q1 2024 | KA12: Q1 2010 | KB12: Q2 2010 | KC12: Q3 2010 | KD12: Q4 2010 | KE12: Q1 2011 | KF12: Q2 2011 | KG12: Q3 2011 | KH12: Q4 2011 | KI12: Q1 2012 | KJ12: Q2 2012 | KK12: Q3 2012 | KL12: Q4 2012 | KM12: Q1 2013 | KN12: Q2 2013 | KO12: Q3 2013 | KP12: Q4 2013 | KQ12: Q1 2014 | KR12: Q2 2014 | KS12: Q3 2014 | KT12: Q4 2014 | KU12: Q1 2015 | KV12: Q2 2015 | KW12: Q3 2015 | KX12: Q4 2015 | KY12: Q1 2016 | KZ12: Q2 2016 | LA12: Q3 2016 | LB12: Q4 2016 | LC12: Q1 2017 | LD12: Q2 2017 | LE12: Q3 2017 | LF12: Q4 2017 | LG12: Q1 2018 | LH12: Q2 2018 | LI12: Q3 2018 | LJ12: Q4 2018 | LK12: Q1 2019 | LL12: Q2 2019 | LM12: Q3 2019 | LN12: Q4 2019 | LO12: Q1 2020 | LP12: Q2 2020 | LQ12: Q3 2020 | LR12: Q4 2020 | LS12: Q1 2021 | LT12: Q2 2021 | LU12: Q3 2021 | LV12: Q4 2021 | LW12: Q1 2022 | LX12: Q2 2022 | LY12: Q3 2022 | LZ12: Q4 2022 | MA12: Q1 2023 | MB12: Q2 2023 | MC12: Q3 2023 | MD12: Q4 2023 | ME12: Q1 2024
B13: Dollars
A14: Total assets | B14: .. | C14: .. | D14: .. | E14: 622328 | F14: .. | G14: .. | H14: .. | I14: 641989 | J14: .. | K14: .. | L14: .. | M14: 681101 | N14: .. | O14: .. | P14: .. | Q14: 718604 | R14: .. | S14: .. | T14: .. | U14: 764153 | V14: .. | W14: .. | X14: .. | Y14: 803842 | Z14: .. | AA14: .. | AB14: .. | AC14: 857986 | AD14: .. | AE14: .. | AF14: .. | AG14: 893533 | AH14: .. | AI14: .. | AJ14: .. | AK14: 887910 | AL14: .. | AM14: .. | AN14: .. | AO14: 942989 | AP14: 914050 | AQ14: 962238 | AR14: 1006339 | AS14: 1044575 | AT14: 1110209 | AU14: 1156751 | AV14: 1195905 | AW14: 1211594 | AX14: 1214538 | AY14: 1156192 | AZ14: 1130975 | BA14: 1134821 | BB14: 1159192 | BC14: 1171626 | BD14: 1147002 | BE14: 1156039 | BF14: 1186363 | BG14: .. | BH14: .. | BI14: .. | BJ14: 57373 | BK14: .. | BL14: .. | BM14: .. | BN14: 58384 | BO14: .. | BP14: .. | BQ14: .. | BR14: 56974 | BS14: .. | BT14: .. | BU14: .. | BV14: 55127 | BW14: .. | BX14: .. | BY14: .. | BZ14: 54832 | CA14: .. | CB14: .. | CC14: .. | CD14: 56577 | CE14: .. | CF14: .. | CG14: .. | CH14: 56535 | CI14: .. | CJ14: .. | CK14: .. | CL14: 57559 | CM14: .. | CN14: .. | CO14: .. | CP14: 66248 | CQ14: .. | CR14: .. | CS14: .. | CT14: 68561 | CU14: 65897 | CV14: 65305 | CW14: 65191 | CX14: 59781 | CY14: 49431 | CZ14: 49960 | DA14: 45923 | DB14: 41097 | DC14: 40446 | DD14: 47350 | DE14: 56530 | DF14: 58444 | DG14: 55136 | DH14: 55413 | DI14: 57804 | DJ14: 60593 | DK14: 58162 | DL14: .. | DM14: .. | DN14: .. | DO14: 143755 | DP14: .. | DQ14: .. | DR14: .. | DS14: 149382 | DT14: .. | DU14: .. | DV14: .. | DW14: 160793 | DX14: .. | DY14: .. | DZ14: .. | EA14: 171429 | EB14: .. | EC14: .. | ED14: .. | EE14: 178845 | EF14: .. | EG14: .. | EH14: .. | EI14: 190393 | EJ14: .. | EK14: .. | EL14: .. | EM14: 204129 | EN14: .. | EO14: .. | EP14: .. | EQ14: 212756 | ER14: .. | ES14: .. | ET14: .. | EU14: 212194 | EV14: .. | EW14: .. | EX14: .. | EY14: 225740 | EZ14: 222392 | FA14: 229405 | FB14: 239796 | FC14: 247213 | FD14: 264593 | FE14: 274008 | FF14: 284910 | FG14: 285691 | FH14: 287726 | FI14: 279390 | FJ14: 270350 | FK14: 271022 | FL14: 275853 | FM14: 277835 | FN14: 273079 | FO14: 276100 | FP14: 279832 | FQ14: .. | FR14: .. | FS14: .. | FT14: 356779 | FU14: .. | FV14: .. | FW14: .. | FX14: 375404 | FY14: .. | FZ14: .. | GA14: .. | GB14: 398516 | GC14: .. | GD14: .. | GE14: .. | GF14: 419331 | GG14: .. | GH14: .. | GI14: .. | GJ14: 444767 | GK14: .. | GL14: .. | GM14: .. | GN14: 466940 | GO14: .. | GP14: .. | GQ14: .. | GR14: 497114 | GS14: .. | GT14: .. | GU14: .. | GV14: 515555 | GW14: .. | GX14: .. | GY14: .. | GZ14: 506548 | HA14: .. | HB14: .. | HC14: .. | HD14: 529477 | HE14: 515887 | HF14: 543187 | HG14: 569001 | HH14: 587560 | HI14: 629812 | HJ14: 658334 | HK14: 689651 | HL14: 705075 | HM14: 711932 | HN14: 674108 | HO14: 657795 | HP14: 653783 | HQ14: 668490 | HR14: 676793 | HS14: 662456 | HT14: 656384 | HU14: 675017 | HV14: .. | HW14: .. | HX14: .. | HY14: 657337 | HZ14: .. | IA14: .. | IB14: .. | IC14: 682427 | ID14: .. | IE14: .. | IF14: .. | IG14: 725971 | IH14: .. | II14: .. | IJ14: .. | IK14: 766960 | IL14: .. | IM14: .. | IN14: .. | IO14: 814295 | IP14: .. | IQ14: .. | IR14: .. | IS14: 856559 | IT14: .. | IU14: .. | IV14: .. | IW14: 912924 | IX14: .. | IY14: .. | IZ14: .. | JA14: 948964 | JB14: .. | JC14: .. | JD14: .. | JE14: 933016 | JF14: .. | JG14: .. | JH14: .. | JI14: 990795 | JJ14: 966947 | JK14: 1014096 | JL14: 1059961 | JM14: 1110189 | JN14: 1186914 | JO14: 1236495 | JP14: 1282096 | JQ14: 1299421 | JR14: 1301117 | JS14: 1243397 | JT14: 1207937 | JU14: 1205986 | JV14: 1232535 | JW14: 1244937 | JX14: 1218190 | JY14: 1224305 | JZ14: 1253928 | KA14: .. | KB14: .. | KC14: .. | KD14: 1896395 | KE14: .. | KF14: .. | KG14: .. | KH14: 1944349 | KI14: .. | KJ14: .. | KK14: .. | KL14: 2063251 | KM14: .. | KN14: .. | KO14: .. | KP14: 2180175 | KQ14: .. | KR14: .. | KS14: .. | KT14: 2328025 | KU14: .. | KV14: .. | KW14: .. | KX14: 2448743 | KY14: .. | KZ14: .. | LA14: .. | LB14: 2619228 | LC14: .. | LD14: .. | LE14: .. | LF14: 2732831 | LG14: .. | LH14: .. | LI14: .. | LJ14: 2721546 | LK14: .. | LL14: .. | LM14: .. | LN14: 2900372 | LO14: 2799128 | LP14: 2959196 | LQ14: 3097745 | LR14: 3218134 | LS14: 3420294 | LT14: 3564956 | LU14: 3676947 | LV14: 3726684 | LW14: 3731469 | LX14: 3536713 | LY14: 3462261 | LZ14: 3484870 | MA14: 3563946 | MB14: 3603153 | MC14: 3523480 | MD14: 3562812 | ME14: 3664878
A15: Financial assets | B15: .. | C15: .. | D15: .. | E15: 333473 | F15: .. | G15: .. | H15: .. | I15: 336850 | J15: .. | K15: .. | L15: .. | M15: 357632 | N15: .. | O15: .. | P15: .. | Q15: 378521 | R15: .. | S15: .. | T15: .. | U15: 409472 | V15: .. | W15: .. | X15: .. | Y15: 426725 | Z15: .. | AA15: .. | AB15: .. | AC15: 453871 | AD15: .. | AE15: .. | AF15: .. | AG15: 474448 | AH15: .. | AI15: .. | AJ15: .. | AK15: 471682 | AL15: .. | AM15: .. | AN15: .. | AO15: 509287 | AP15: 476010 | AQ15: 507061 | AR15: 529110 | AS15: 544932 | AT15: 565225 | AU15: 588120 | AV15: 592085 | AW15: 590985 | AX15: 574253 | AY15: 544621 | AZ15: 542952 | BA15: 556352 | BB15: 567752 | BC15: 571559 | BD15: 558239 | BE15: 578383 | BF15: 597772 | BG15: .. | BH15: .. | BI15: .. | BJ15: 8044 | BK15: .. | BL15: .. | BM15: .. | BN15: 7940 | BO15: .. | BP15: .. | BQ15: .. | BR15: 8140 | BS15: .. | BT15: .. | BU15: .. | BV15: 8554 | BW15: .. | BX15: .. | BY15: .. | BZ15: 9108 | CA15: .. | CB15: .. | CC15: .. | CD15: 10005 | CE15: .. | CF15: .. | CG15: .. | CH15: 10729 | CI15: .. | CJ15: .. | CK15: .. | CL15: 11207 | CM15: .. | CN15: .. | CO15: .. | CP15: 11595 | CQ15: .. | CR15: .. | CS15: .. | CT15: 12033 | CU15: 11071 | CV15: 10851 | CW15: 11310 | CX15: 11217 | CY15: 11097 | CZ15: 11411 | DA15: 10902 | DB15: 10870 | DC15: 10844 | DD15: 10666 | DE15: 11266 | DF15: 11434 | DG15: 11466 | DH15: 11676 | DI15: 11563 | DJ15: 11805 | DK15: 11974 | DL15: .. | DM15: .. | DN15: .. | DO15: 33604 | DP15: .. | DQ15: .. | DR15: .. | DS15: 34427 | DT15: .. | DU15: .. | DV15: .. | DW15: 37781 | DX15: .. | DY15: .. | DZ15: .. | EA15: 42182 | EB15: .. | EC15: .. | ED15: .. | EE15: 47658 | EF15: .. | EG15: .. | EH15: .. | EI15: 52641 | EJ15: .. | EK15: .. | EL15: .. | EM15: 57969 | EN15: .. | EO15: .. | EP15: .. | EQ15: 61395 | ER15: .. | ES15: .. | ET15: .. | EU15: 62074 | EV15: .. | EW15: .. | EX15: .. | EY15: 68341 | EZ15: 65206 | FA15: 69532 | FB15: 72758 | FC15: 75502 | FD15: 79710 | FE15: 83596 | FF15: 87215 | FG15: 88705 | FH15: 87549 | FI15: 82224 | FJ15: 80055 | FK15: 80721 | FL15: 82931 | FM15: 83336 | FN15: 81333 | FO15: 82344 | FP15: 85275 | FQ15: .. | FR15: .. | FS15: .. | FT15: 113248 | FU15: .. | FV15: .. | FW15: .. | FX15: 117214 | FY15: .. | FZ15: .. | GA15: .. | GB15: 125834 | GC15: .. | GD15: .. | GE15: .. | GF15: 136523 | GG15: .. | GH15: .. | GI15: .. | GJ15: 150937 | GK15: .. | GL15: .. | GM15: .. | GN15: 164004 | GO15: .. | GP15: .. | GQ15: .. | GR15: 177986 | GS15: .. | GT15: .. | GU15: .. | GV15: 187480 | GW15: .. | GX15: .. | GY15: .. | GZ15: 184269 | HA15: .. | HB15: .. | HC15: .. | HD15: 199834 | HE15: 188969 | HF15: 198424 | HG15: 206509 | HH15: 212961 | HI15: 223758 | HJ15: 231704 | HK15: 235252 | HL15: 236487 | HM15: 232514 | HN15: 221395 | HO15: 219229 | HP15: 221232 | HQ15: 225068 | HR15: 226610 | HS15: 222206 | HT15: 227456 | HU15: 233758 | HV15: .. | HW15: .. | HX15: .. | HY15: 306266 | HZ15: .. | IA15: .. | IB15: .. | IC15: 312937 | ID15: .. | IE15: .. | IF15: .. | IG15: 333797 | IH15: .. | II15: .. | IJ15: .. | IK15: 354819 | IL15: .. | IM15: .. | IN15: .. | IO15: 386305 | IP15: .. | IQ15: .. | IR15: .. | IS15: 404421 | IT15: .. | IU15: .. | IV15: .. | IW15: 432377 | IX15: .. | IY15: .. | IZ15: .. | JA15: 452087 | JB15: .. | JC15: .. | JD15: .. | JE15: 435715 | JF15: .. | JG15: .. | JH15: .. | JI15: 460743 | JJ15: 428186 | JK15: 455456 | JL15: 472439 | JM15: 485744 | JN15: 502522 | JO15: 521710 | JP15: 524116 | JQ15: 524105 | JR15: 510683 | JS15: 479341 | JT15: 476162 | JU15: 486292 | JV15: 497142 | JW15: 500615 | JX15: 487259 | JY15: 503197 | JZ15: 517997 | KA15: .. | KB15: .. | KC15: .. | KD15: 1206204 | KE15: .. | KF15: .. | KG15: .. | KH15: 1211731 | KI15: .. | KJ15: .. | KK15: .. | KL15: 1282607 | KM15: .. | KN15: .. | KO15: .. | KP15: 1350527 | KQ15: .. | KR15: .. | KS15: .. | KT15: 1453350 | KU15: .. | KV15: .. | KW15: .. | KX15: 1502554 | KY15: .. | KZ15: .. | LA15: .. | LB15: 1590294 | LC15: .. | LD15: .. | LE15: .. | LF15: 1660072 | LG15: .. | LH15: .. | LI15: .. | LJ15: 1664755 | LK15: .. | LL15: .. | LM15: .. | LN15: 1805484 | LO15: 1686616 | LP15: 1801042 | LQ15: 1882535 | LR15: 1939238 | LS15: 2009038 | LT15: 2092179 | LU15: 2102941 | LV15: 2094758 | LW15: 2029675 | LX15: 1929481 | LY15: 1928046 | LZ15: 1982080 | MA15: 2022152 | MB15: 2035559 | MC15: 1988833 | MD15: 2067110 | ME15: 2139853
A16: Life insurance and pensions 3 | B16: .. | C16: .. | D16: .. | E16: 117973 | F16: .. | G16: .. | H16: .. | I16: 126773 | J16: .. | K16: .. | L16: .. | M16: 135424 | N16: .. | O16: .. | P16: .. | Q16: 139755 | R16: .. | S16: .. | T16: .. | U16: 151269 | V16: .. | W16: .. | X16: .. | Y16: 155575 | Z16: .. | AA16: .. | AB16: .. | AC16: 162531 | AD16: .. | AE16: .. | AF16: .. | AG16: 167154 | AH16: .. | AI16: .. | AJ16: .. | AK16: 164504 | AL16: .. | AM16: .. | AN16: .. | AO16: 178136 | AP16: 170097 | AQ16: 178252 | AR16: 183091 | AS16: 186538 | AT16: 187920 | AU16: 193075 | AV16: 191060 | AW16: 189471 | AX16: 180304 | AY16: 167824 | AZ16: 167578 | BA16: 170031 | BB16: 172701 | BC16: 172643 | BD16: 167415 | BE16: 173931 | BF16: 177962 | BG16: .. | BH16: .. | BI16: .. | BJ16: 2655 | BK16: .. | BL16: .. | BM16: .. | BN16: 2665 | BO16: .. | BP16: .. | BQ16: .. | BR16: 2678 | BS16: .. | BT16: .. | BU16: .. | BV16: 2651 | BW16: .. | BX16: .. | BY16: .. | BZ16: 2679 | CA16: .. | CB16: .. | CC16: .. | CD16: 2979 | CE16: .. | CF16: .. | CG16: .. | CH16: 3025 | CI16: .. | CJ16: .. | CK16: .. | CL16: 3063 | CM16: .. | CN16: .. | CO16: .. | CP16: 3445 | CQ16: .. | CR16: .. | CS16: .. | CT16: 3672 | CU16: 3471 | CV16: 3233 | CW16: 3395 | CX16: 3252 | CY16: 2861 | CZ16: 2879 | DA16: 2752 | DB16: 2626 | DC16: 2771 | DD16: 2891 | DE16: 3051 | DF16: 3077 | DG16: 2922 | DH16: 3080 | DI16: 3180 | DJ16: 3148 | DK16: 3030 | DL16: .. | DM16: .. | DN16: .. | DO16: 12515 | DP16: .. | DQ16: .. | DR16: .. | DS16: 13065 | DT16: .. | DU16: .. | DV16: .. | DW16: 14785 | DX16: .. | DY16: .. | DZ16: .. | EA16: 16987 | EB16: .. | EC16: .. | ED16: .. | EE16: 20221 | EF16: .. | EG16: .. | EH16: .. | EI16: 22847 | EJ16: .. | EK16: .. | EL16: .. | EM16: 26126 | EN16: .. | EO16: .. | EP16: .. | EQ16: 27799 | ER16: .. | ES16: .. | ET16: .. | EU16: 25446 | EV16: .. | EW16: .. | EX16: .. | EY16: 25942 | EZ16: 24712 | FA16: 26082 | FB16: 27481 | FC16: 28922 | FD16: 30416 | FE16: 31728 | FF16: 33569 | FG16: 34161 | FH16: 33452 | FI16: 30975 | FJ16: 30491 | FK16: 30332 | FL16: 31658 | FM16: 31683 | FN16: 30608 | FO16: 30469 | FP16: 31963 | FQ16: .. | FR16: .. | FS16: .. | FT16: 47708 | FU16: .. | FV16: .. | FW16: .. | FX16: 51067 | FY16: .. | FZ16: .. | GA16: .. | GB16: 55372 | GC16: .. | GD16: .. | GE16: .. | GF16: 60720 | GG16: .. | GH16: .. | GI16: .. | GJ16: 68570 | GK16: .. | GL16: .. | GM16: .. | GN16: 76566 | GO16: .. | GP16: .. | GQ16: .. | GR16: 83133 | GS16: .. | GT16: .. | GU16: .. | GV16: 87214 | GW16: .. | GX16: .. | GY16: .. | GZ16: 84335 | HA16: .. | HB16: .. | HC16: .. | HD16: 91325 | HE16: 87809 | HF16: 91706 | HG16: 94276 | HH16: 95642 | HI16: 99136 | HJ16: 102682 | HK16: 104047 | HL16: 104724 | HM16: 103386 | HN16: 97378 | HO16: 95660 | HP16: 96761 | HQ16: 98229 | HR16: 98742 | HS16: 96228 | HT16: 99003 | HU16: 100777 | HV16: .. | HW16: .. | HX16: .. | HY16: 148070 | HZ16: .. | IA16: .. | IB16: .. | IC16: 158053 | ID16: .. | IE16: .. | IF16: .. | IG16: 170107 | IH16: .. | II16: .. | IJ16: .. | IK16: 177861 | IL16: .. | IM16: .. | IN16: .. | IO16: 194293 | IP16: .. | IQ16: .. | IR16: .. | IS16: 203744 | IT16: .. | IU16: .. | IV16: .. | IW16: 217488 | IX16: .. | IY16: .. | IZ16: .. | JA16: 225563 | JB16: .. | JC16: .. | JD16: .. | JE16: 220511 | JF16: .. | JG16: .. | JH16: .. | JI16: 237268 | JJ16: 224306 | JK16: 235790 | JL16: 242979 | JM16: 248865 | JN16: 253599 | JO16: 261193 | JP16: 258794 | JQ16: 258200 | JR16: 247494 | JS16: 230830 | JT16: 230869 | JU16: 232411 | JV16: 237756 | JW16: 238416 | JX16: 230937 | JY16: 238243 | JZ16: 243281 | KA16: .. | KB16: .. | KC16: .. | KD16: 378917 | KE16: .. | KF16: .. | KG16: .. | KH16: 409012 | KI16: .. | KJ16: .. | KK16: .. | KL16: 434180 | KM16: .. | KN16: .. | KO16: .. | KP16: 440558 | KQ16: .. | KR16: .. | KS16: .. | KT16: 470583 | KU16: .. | KV16: .. | KW16: .. | KX16: 471741 | KY16: .. | KZ16: .. | LA16: .. | LB16: 482883 | LC16: .. | LD16: .. | LE16: .. | LF16: 492132 | LG16: .. | LH16: .. | LI16: .. | LJ16: 488780 | LK16: .. | LL16: .. | LM16: .. | LN16: 532472 | LO16: 510185 | LP16: 534451 | LQ16: 547324 | LR16: 556007 | LS16: 553590 | LT16: 566895 | LU16: 556139 | LV16: 547644 | LW16: 514418 | LX16: 477044 | LY16: 477817 | LZ16: 487577 | MA16: 492941 | MB16: 491294 | MC16: 476125 | MD16: 498793 | ME16: 510759
A17: Other financial assets 4 | B17: .. | C17: .. | D17: .. | E17: 215500 | F17: .. | G17: .. | H17: .. | I17: 210077 | J17: .. | K17: .. | L17: .. | M17: 222208 | N17: .. | O17: .. | P17: .. | Q17: 238766 | R17: .. | S17: .. | T17: .. | U17: 258202 | V17: .. | W17: .. | X17: .. | Y17: 271150 | Z17: .. | AA17: .. | AB17: .. | AC17: 291340 | AD17: .. | AE17: .. | AF17: .. | AG17: 307294 | AH17: .. | AI17: .. | AJ17: .. | AK17: 307178 | AL17: .. | AM17: .. | AN17: .. | AO17: 331151 | AP17: 305913 | AQ17: 328809 | AR17: 346019 | AS17: 358395 | AT17: 377305 | AU17: 395045 | AV17: 401025 | AW17: 401514 | AX17: 393949 | AY17: 376798 | AZ17: 375374 | BA17: 386320 | BB17: 395051 | BC17: 398916 | BD17: 390823 | BE17: 404452 | BF17: 419810 | BG17: .. | BH17: .. | BI17: .. | BJ17: 5389 | BK17: .. | BL17: .. | BM17: .. | BN17: 5275 | BO17: .. | BP17: .. | BQ17: .. | BR17: 5463 | BS17: .. | BT17: .. | BU17: .. | BV17: 5903 | BW17: .. | BX17: .. | BY17: .. | BZ17: 6430 | CA17: .. | CB17: .. | CC17: .. | CD17: 7026 | CE17: .. | CF17: .. | CG17: .. | CH17: 7704 | CI17: .. | CJ17: .. | CK17: .. | CL17: 8145 | CM17: .. | CN17: .. | CO17: .. | CP17: 8150 | CQ17: .. | CR17: .. | CS17: .. | CT17: 8361 | CU17: 7600 | CV17: 7618 | CW17: 7915 | CX17: 7964 | CY17: 8236 | CZ17: 8532 | DA17: 8150 | DB17: 8244 | DC17: 8072 | DD17: 7775 | DE17: 8215 | DF17: 8357 | DG17: 8544 | DH17: 8596 | DI17: 8383 | DJ17: 8657 | DK17: 8944 | DL17: .. | DM17: .. | DN17: .. | DO17: 21089 | DP17: .. | DQ17: .. | DR17: .. | DS17: 21362 | DT17: .. | DU17: .. | DV17: .. | DW17: 22996 | DX17: .. | DY17: .. | DZ17: .. | EA17: 25196 | EB17: .. | EC17: .. | ED17: .. | EE17: 27436 | EF17: .. | EG17: .. | EH17: .. | EI17: 29795 | EJ17: .. | EK17: .. | EL17: .. | EM17: 31843 | EN17: .. | EO17: .. | EP17: .. | EQ17: 33595 | ER17: .. | ES17: .. | ET17: .. | EU17: 36628 | EV17: .. | EW17: .. | EX17: .. | EY17: 42398 | EZ17: 40493 | FA17: 43450 | FB17: 45277 | FC17: 46580 | FD17: 49294 | FE17: 51868 | FF17: 53646 | FG17: 54544 | FH17: 54098 | FI17: 51249 | FJ17: 49564 | FK17: 50390 | FL17: 51274 | FM17: 51653 | FN17: 50725 | FO17: 51876 | FP17: 53313 | FQ17: .. | FR17: .. | FS17: .. | FT17: 65540 | FU17: .. | FV17: .. | FW17: .. | FX17: 66147 | FY17: .. | FZ17: .. | GA17: .. | GB17: 70461 | GC17: .. | GD17: .. | GE17: .. | GF17: 75803 | GG17: .. | GH17: .. | GI17: .. | GJ17: 82366 | GK17: .. | GL17: .. | GM17: .. | GN17: 87437 | GO17: .. | GP17: .. | GQ17: .. | GR17: 94853 | GS17: .. | GT17: .. | GU17: .. | GV17: 100265 | GW17: .. | GX17: .. | GY17: .. | GZ17: 99934 | HA17: .. | HB17: .. | HC17: .. | HD17: 108509 | HE17: 101161 | HF17: 106717 | HG17: 112232 | HH17: 117319 | HI17: 124622 | HJ17: 129022 | HK17: 131205 | HL17: 131763 | HM17: 129129 | HN17: 124017 | HO17: 123569 | HP17: 124471 | HQ17: 126839 | HR17: 127868 | HS17: 125978 | HT17: 128453 | HU17: 132981 | HV17: .. | HW17: .. | HX17: .. | HY17: 158197 | HZ17: .. | IA17: .. | IB17: .. | IC17: 154883 | ID17: .. | IE17: .. | IF17: .. | IG17: 163690 | IH17: .. | II17: .. | IJ17: .. | IK17: 176958 | IL17: .. | IM17: .. | IN17: .. | IO17: 192012 | IP17: .. | IQ17: .. | IR17: .. | IS17: 200677 | IT17: .. | IU17: .. | IV17: .. | IW17: 214889 | IX17: .. | IY17: .. | IZ17: .. | JA17: 226523 | JB17: .. | JC17: .. | JD17: .. | JE17: 215204 | JF17: .. | JG17: .. | JH17: .. | JI17: 223475 | JJ17: 203881 | JK17: 219666 | JL17: 229460 | JM17: 236878 | JN17: 248923 | JO17: 260518 | JP17: 265321 | JQ17: 265905 | JR17: 263190 | JS17: 248511 | JT17: 245293 | JU17: 253881 | JV17: 259386 | JW17: 262199 | JX17: 256322 | JY17: 264955 | JZ17: 274716 | KA17: .. | KB17: .. | KC17: .. | KD17: 827287 | KE17: .. | KF17: .. | KG17: .. | KH17: 802719 | KI17: .. | KJ17: .. | KK17: .. | KL17: 848428 | KM17: .. | KN17: .. | KO17: .. | KP17: 909970 | KQ17: .. | KR17: .. | KS17: .. | KT17: 982767 | KU17: .. | KV17: .. | KW17: .. | KX17: 1030814 | KY17: .. | KZ17: .. | LA17: .. | LB17: 1107411 | LC17: .. | LD17: .. | LE17: .. | LF17: 1167940 | LG17: .. | LH17: .. | LI17: .. | LJ17: 1175974 | LK17: .. | LL17: .. | LM17: .. | LN17: 1273012 | LO17: 1176430 | LP17: 1266592 | LQ17: 1335211 | LR17: 1383231 | LS17: 1455448 | LT17: 1525285 | LU17: 1546802 | LV17: 1547114 | LW17: 1515257 | LX17: 1452436 | LY17: 1450229 | LZ17: 1494503 | MA17: 1529211 | MB17: 1544265 | MC17: 1512709 | MD17: 1568318 | ME17: 1629093
A18: Non-financial assets | B18: .. | C18: .. | D18: .. | E18: 288854 | F18: .. | G18: .. | H18: .. | I18: 305139 | J18: .. | K18: .. | L18: .. | M18: 323469 | N18: .. | O18: .. | P18: .. | Q18: 340083 | R18: .. | S18: .. | T18: .. | U18: 354681 | V18: .. | W18: .. | X18: .. | Y18: 377117 | Z18: .. | AA18: .. | AB18: .. | AC18: 404115 | AD18: .. | AE18: .. | AF18: .. | AG18: 419085 | AH18: .. | AI18: .. | AJ18: .. | AK18: 416228 | AL18: .. | AM18: .. | AN18: .. | AO18: 433702 | AP18: 438040 | AQ18: 455177 | AR18: 477229 | AS18: 499643 | AT18: 544984 | AU18: 568631 | AV18: 603820 | AW18: 620609 | AX18: 640285 | AY18: 611570 | AZ18: 588023 | BA18: 578469 | BB18: 591440 | BC18: 600067 | BD18: 588763 | BE18: 577656 | BF18: 588592 | BG18: .. | BH18: .. | BI18: .. | BJ18: 49329 | BK18: .. | BL18: .. | BM18: .. | BN18: 50443 | BO18: .. | BP18: .. | BQ18: .. | BR18: 48834 | BS18: .. | BT18: .. | BU18: .. | BV18: 46573 | BW18: .. | BX18: .. | BY18: .. | BZ18: 45723 | CA18: .. | CB18: .. | CC18: .. | CD18: 46572 | CE18: .. | CF18: .. | CG18: .. | CH18: 45806 | CI18: .. | CJ18: .. | CK18: .. | CL18: 46351 | CM18: .. | CN18: .. | CO18: .. | CP18: 54652 | CQ18: .. | CR18: .. | CS18: .. | CT18: 56528 | CU18: 54825 | CV18: 54454 | CW18: 53881 | CX18: 48564 | CY18: 38334 | CZ18: 38549 | DA18: 35021 | DB18: 30227 | DC18: 29602 | DD18: 36685 | DE18: 45264 | DF18: 47010 | DG18: 43670 | DH18: 43737 | DI18: 46241 | DJ18: 48788 | DK18: 46188 | DL18: .. | DM18: .. | DN18: .. | DO18: 110150 | DP18: .. | DQ18: .. | DR18: .. | DS18: 114955 | DT18: .. | DU18: .. | DV18: .. | DW18: 123012 | DX18: .. | DY18: .. | DZ18: .. | EA18: 129246 | EB18: .. | EC18: .. | ED18: .. | EE18: 131187 | EF18: .. | EG18: .. | EH18: .. | EI18: 137752 | EJ18: .. | EK18: .. | EL18: .. | EM18: 146161 | EN18: .. | EO18: .. | EP18: .. | EQ18: 151361 | ER18: .. | ES18: .. | ET18: .. | EU18: 150120 | EV18: .. | EW18: .. | EX18: .. | EY18: 157399 | EZ18: 157186 | FA18: 159874 | FB18: 167038 | FC18: 171711 | FD18: 184883 | FE18: 190412 | FF18: 197694 | FG18: 196986 | FH18: 200176 | FI18: 197166 | FJ18: 190296 | FK18: 190301 | FL18: 192922 | FM18: 194498 | FN18: 191746 | FO18: 193756 | FP18: 194557 | FQ18: .. | FR18: .. | FS18: .. | FT18: 243531 | FU18: .. | FV18: .. | FW18: .. | FX18: 258190 | FY18: .. | FZ18: .. | GA18: .. | GB18: 272682 | GC18: .. | GD18: .. | GE18: .. | GF18: 282808 | GG18: .. | GH18: .. | GI18: .. | GJ18: 293830 | GK18: .. | GL18: .. | GM18: .. | GN18: 302936 | GO18: .. | GP18: .. | GQ18: .. | GR18: 319128 | GS18: .. | GT18: .. | GU18: .. | GV18: 328075 | GW18: .. | GX18: .. | GY18: .. | GZ18: 322279 | HA18: .. | HB18: .. | HC18: .. | HD18: 329643 | HE18: 326917 | HF18: 344763 | HG18: 362493 | HH18: 374599 | HI18: 406054 | HJ18: 426630 | HK18: 454398 | HL18: 468589 | HM18: 479417 | HN18: 452713 | HO18: 438567 | HP18: 432551 | HQ18: 443422 | HR18: 450184 | HS18: 440250 | HT18: 428927 | HU18: 441258 | HV18: .. | HW18: .. | HX18: .. | HY18: 351070 | HZ18: .. | IA18: .. | IB18: .. | IC18: 369490 | ID18: .. | IE18: .. | IF18: .. | IG18: 392174 | IH18: .. | II18: .. | IJ18: .. | IK18: 412141 | IL18: .. | IM18: .. | IN18: .. | IO18: 427990 | IP18: .. | IQ18: .. | IR18: .. | IS18: 452138 | IT18: .. | IU18: .. | IV18: .. | IW18: 480546 | IX18: .. | IY18: .. | IZ18: .. | JA18: 496877 | JB18: .. | JC18: .. | JD18: .. | JE18: 497300 | JF18: .. | JG18: .. | JH18: .. | JI18: 530053 | JJ18: 538761 | JK18: 558639 | JL18: 587522 | JM18: 624445 | JN18: 684391 | JO18: 714784 | JP18: 757981 | JQ18: 775316 | JR18: 790433 | JS18: 764056 | JT18: 731775 | JU18: 719693 | JV18: 735393 | JW18: 744322 | JX18: 730931 | JY18: 721108 | JZ18: 735931 | KA18: .. | KB18: .. | KC18: .. | KD18: 690191 | KE18: .. | KF18: .. | KG18: .. | KH18: 732619 | KI18: .. | KJ18: .. | KK18: .. | KL18: 780644 | KM18: .. | KN18: .. | KO18: .. | KP18: 829647 | KQ18: .. | KR18: .. | KS18: .. | KT18: 874675 | KU18: .. | KV18: .. | KW18: .. | KX18: 946189 | KY18: .. | KZ18: .. | LA18: .. | LB18: 1028934 | LC18: .. | LD18: .. | LE18: .. | LF18: 1072759 | LG18: .. | LH18: .. | LI18: .. | LJ18: 1056791 | LK18: .. | LL18: .. | LM18: .. | LN18: 1094887 | LO18: 1112512 | LP18: 1158153 | LQ18: 1215210 | LR18: 1278895 | LS18: 1411256 | LT18: 1472777 | LU18: 1574005 | LV18: 1631926 | LW18: 1701794 | LX18: 1607232 | LY18: 1534215 | LZ18: 1502791 | MA18: 1541794 | MB18: 1567594 | MC18: 1534646 | MD18: 1495702 | ME18: 1525025
A19: Real estate | B19: .. | C19: .. | D19: .. | E19: 249348 | F19: .. | G19: .. | H19: .. | I19: 265356 | J19: .. | K19: .. | L19: .. | M19: 282961 | N19: .. | O19: .. | P19: .. | Q19: 298499 | R19: .. | S19: .. | T19: .. | U19: 311484 | V19: .. | W19: .. | X19: .. | Y19: 331993 | Z19: .. | AA19: .. | AB19: .. | AC19: 357082 | AD19: .. | AE19: .. | AF19: .. | AG19: 370992 | AH19: .. | AI19: .. | AJ19: .. | AK19: 367364 | AL19: .. | AM19: .. | AN19: .. | AO19: 383906 | AP19: 389447 | AQ19: 406460 | AR19: 426249 | AS19: 448651 | AT19: 493299 | AU19: 515047 | AV19: 548342 | AW19: 566129 | AX19: 585285 | AY19: 554822 | AZ19: 530835 | BA19: 521783 | BB19: 535719 | BC19: 543482 | BD19: 531709 | BE19: 520496 | BF19: 532186 | BG19: .. | BH19: .. | BI19: .. | BJ19: 36798 | BK19: .. | BL19: .. | BM19: .. | BN19: 37903 | BO19: .. | BP19: .. | BQ19: .. | BR19: 36295 | BS19: .. | BT19: .. | BU19: .. | BV19: 33927 | BW19: .. | BX19: .. | BY19: .. | BZ19: 32756 | CA19: .. | CB19: .. | CC19: .. | CD19: 33048 | CE19: .. | CF19: .. | CG19: .. | CH19: 32041 | CI19: .. | CJ19: .. | CK19: .. | CL19: 32422 | CM19: .. | CN19: .. | CO19: .. | CP19: 39114 | CQ19: .. | CR19: .. | CS19: .. | CT19: 40307 | CU19: 38956 | CV19: 38634 | CW19: 37781 | CX19: 33198 | CY19: 23393 | CZ19: 23173 | DA19: 19479 | DB19: 15265 | DC19: 14615 | DD19: 21009 | DE19: 29297 | DF19: 30933 | DG19: 28011 | DH19: 27934 | DI19: 30244 | DJ19: 32600 | DK19: 30214 | DL19: .. | DM19: .. | DN19: .. | DO19: 87900 | DP19: .. | DQ19: .. | DR19: .. | DS19: 92349 | DT19: .. | DU19: .. | DV19: .. | DW19: 99591 | DX19: .. | DY19: .. | DZ19: .. | EA19: 104704 | EB19: .. | EC19: .. | ED19: .. | EE19: 105439 | EF19: .. | EG19: .. | EH19: .. | EI19: 110543 | EJ19: .. | EK19: .. | EL19: .. | EM19: 117630 | EN19: .. | EO19: .. | EP19: .. | EQ19: 121973 | ER19: .. | ES19: .. | ET19: .. | EU19: 120370 | EV19: .. | EW19: .. | EX19: .. | EY19: 126803 | EZ19: 127272 | FA19: 129748 | FB19: 135463 | FC19: 138945 | FD19: 152267 | FE19: 156332 | FF19: 162619 | FG19: 162519 | FH19: 165452 | FI19: 161634 | FJ19: 153825 | FK19: 154259 | FL19: 157405 | FM19: 158498 | FN19: 155460 | FO19: 157324 | FP19: 158559 | FQ19: .. | FR19: .. | FS19: .. | FT19: 208044 | FU19: .. | FV19: .. | FW19: .. | FX19: 222411 | FY19: .. | FZ19: .. | GA19: .. | GB19: 236376 | GC19: .. | GD19: .. | GE19: .. | GF19: 245803 | GG19: .. | GH19: .. | GI19: .. | GJ19: 255604 | GK19: .. | GL19: .. | GM19: .. | GN19: 263313 | GO19: .. | GP19: .. | GQ19: .. | GR19: 277737 | GS19: .. | GT19: .. | GU19: .. | GV19: 285683 | GW19: .. | GX19: .. | GY19: .. | GZ19: 278320 | HA19: .. | HB19: .. | HC19: .. | HD19: 284590 | HE19: 283142 | HF19: 299911 | HG19: 315538 | HH19: 328547 | HI19: 358988 | HJ19: 378025 | HK19: 403531 | HL19: 417963 | HM19: 428263 | HN19: 400260 | HO19: 386946 | HP19: 380774 | HQ19: 392424 | HR19: 398290 | HS19: 388680 | HT19: 376861 | HU19: 389796 | HV19: .. | HW19: .. | HX19: .. | HY19: 305194 | HZ19: .. | IA19: .. | IB19: .. | IC19: 323425 | ID19: .. | IE19: .. | IF19: .. | IG19: 345078 | IH19: .. | II19: .. | IJ19: .. | IK19: 363119 | IL19: .. | IM19: .. | IN19: .. | IO19: 375985 | IP19: .. | IQ19: .. | IR19: .. | IS19: 396763 | IT19: .. | IU19: .. | IV19: .. | IW19: 422127 | IX19: .. | IY19: .. | IZ19: .. | JA19: 436887 | JB19: .. | JC19: .. | JD19: .. | JE19: 438580 | JF19: .. | JG19: .. | JH19: .. | JI19: 470776 | JJ19: 481160 | JK19: 501714 | JL19: 527625 | JM19: 563982 | JN19: 622561 | JO19: 650709 | JP19: 691587 | JQ19: 710377 | JR19: 724475 | JS19: 695856 | JT19: 662907 | JU19: 652367 | JV19: 669221 | JW19: 676992 | JX19: 662386 | JY19: 653417 | JZ19: 668867 | KA19: .. | KB19: .. | KC19: .. | KD19: 608802 | KE19: .. | KF19: .. | KG19: .. | KH19: 650694 | KI19: .. | KJ19: .. | KK19: .. | KL19: 697466 | KM19: .. | KN19: .. | KO19: .. | KP19: 744942 | KQ19: .. | KR19: .. | KS19: .. | KT19: 787635 | KU19: .. | KV19: .. | KW19: .. | KX19: 856299 | KY19: .. | KZ19: .. | LA19: .. | LB19: 935876 | LC19: .. | LD19: .. | LE19: .. | LF19: 977995 | LG19: .. | LH19: .. | LI19: .. | LJ19: 960437 | LK19: .. | LL19: .. | LM19: .. | LN19: 997054 | LO19: 1016704 | LP19: 1062293 | LQ19: 1114839 | LR19: 1178581 | LS19: 1309284 | LT19: 1366998 | LU19: 1464494 | LV19: 1524520 | LW19: 1593617 | LX19: 1495350 | LY19: 1421201 | LZ19: 1390585 | MA19: 1431533 | MB19: 1455698 | MC19: 1421775 | MD19: 1382276 | ME19: 1413495
